Workbook

Sheet Executive Dashboard
A1: Amazon Marketplace Analytics Dashboard
A3: Total Revenue | D3: Total Spend | G3: Total Orders | J3: Total Sessions
A4: =SUM('Raw Data'!Q:Q) -> 8635123 | D4: =SUM('Raw Data'!R:R) -> 2458385 | G4: =SUM('Raw Data'!O:O) -> 80509 | J4: =SUM('Raw Data'!K:K) -> 1486921
A6: Conversion Rate | D6: ROAS | G6: Average Retention | J6: Avg Landing Score
A7: =C5/F5 -> #DIV/0! | D7: =C4/C3 -> #DIV/0! | G7: =AVERAGE('Raw Data'!Y:Y) -> 0.41705708 | J7: =AVERAGE('Raw Data'!AA:AA) -> 79.925
A10: Channel Performance Summary
A11: Channel | B11: Revenue | C11: Spend | D11: Orders | E11: Sessions | F11: Conversion Rate | G11: ROAS | H11: CPA | I11: Avg Retention
A12: Organic Search | B12: =SUMIF('Raw Data'!$C:$C,A12,'Raw Data'!$Q:$Q) -> 1220085 | C12: =SUMIF('Raw Data'!$C:$C,A12,'Raw Data'!$R:$R) -> 0 | D12: =SUMIF('Raw Data'!$C:$C,A12,'Raw Data'!$O:$O) -> 11320 | E12: =SUMIF('Raw Data'!$C:$C,A12,'Raw Data'!$K:$K) -> 225444 | F12: =IFERROR(D12/E12,0) -> 0.050212026 | G12: =IFERROR(B12/C12,0) -> 0 | H12: =IFERROR(C12/D12,0) -> 0 | I12: =AVERAGEIF('Raw Data'!$C:$C,A12,'Raw Data'!$Y:$Y) -> 0.44887632
A13: Paid Search | B13: =SUMIF('Raw Data'!$C:$C,A13,'Raw Data'!$Q:$Q) -> 2309514 | C13: =SUMIF('Raw Data'!$C:$C,A13,'Raw Data'!$R:$R) -> 1063114 | D13: =SUMIF('Raw Data'!$C:$C,A13,'Raw Data'!$O:$O) -> 19798 | E13: =SUMIF('Raw Data'!$C:$C,A13,'Raw Data'!$K:$K) -> 352054 | F13: =IFERROR(D13/E13,0) -> 0.056235691 | G13: =IFERROR(B13/C13,0) -> 2.1724048 | H13: =IFERROR(C13/D13,0) -> 53.69805 | I13: =AVERAGEIF('Raw Data'!$C:$C,A13,'Raw Data'!$Y:$Y) -> 0.38816786
A14: Paid Social | B14: =SUMIF('Raw Data'!$C:$C,A14,'Raw Data'!$Q:$Q) -> 1466490 | C14: =SUMIF('Raw Data'!$C:$C,A14,'Raw Data'!$R:$R) -> 800509 | D14: =SUMIF('Raw Data'!$C:$C,A14,'Raw Data'!$O:$O) -> 12427 | E14: =SUMIF('Raw Data'!$C:$C,A14,'Raw Data'!$K:$K) -> 306181 | F14: =IFERROR(D14/E14,0) -> 0.040587104 | G14: =IFERROR(B14/C14,0) -> 1.8319469 | H14: =IFERROR(C14/D14,0) -> 64.416915 | I14: =AVERAGEIF('Raw Data'!$C:$C,A14,'Raw Data'!$Y:$Y) -> 0.39225814
A15: Email | B15: =SUMIF('Raw Data'!$C:$C,A15,'Raw Data'!$Q:$Q) -> 1268313 | C15: =SUMIF('Raw Data'!$C:$C,A15,'Raw Data'!$R:$R) -> 594762 | D15: =SUMIF('Raw Data'!$C:$C,A15,'Raw Data'!$O:$O) -> 12056 | E15: =SUMIF('Raw Data'!$C:$C,A15,'Raw Data'!$K:$K) -> 164370 | F15: =IFERROR(D15/E15,0) -> 0.073346718 | G15: =IFERROR(B15/C15,0) -> 2.1324715 | H15: =IFERROR(C15/D15,0) -> 49.333278 | I15: =AVERAGEIF('Raw Data'!$C:$C,A15,'Raw Data'!$Y:$Y) -> 0.41185172
A16: Referral | B16: =SUMIF('Raw Data'!$C:$C,A16,'Raw Data'!$Q:$Q) -> 1341614 | C16: =SUMIF('Raw Data'!$C:$C,A16,'Raw Data'!$R:$R) -> 0 | D16: =SUMIF('Raw Data'!$C:$C,A16,'Raw Data'!$O:$O) -> 14939 | E16: =SUMIF('Raw Data'!$C:$C,A16,'Raw Data'!$K:$K) -> 228117 | F16: =IFERROR(D16/E16,0) -> 0.065488324 | G16: =IFERROR(B16/C16,0) -> 0 | H16: =IFERROR(C16/D16,0) -> 0 | I16: =AVERAGEIF('Raw Data'!$C:$C,A16,'Raw Data'!$Y:$Y) -> 0.43745
A17: Direct | B17: =SUMIF('Raw Data'!$C:$C,A17,'Raw Data'!$Q:$Q) -> 1029107 | C17: =SUMIF('Raw Data'!$C:$C,A17,'Raw Data'!$R:$R) -> 0 | D17: =SUMIF('Raw Data'!$C:$C,A17,'Raw Data'!$O:$O) -> 9969 | E17: =SUMIF('Raw Data'!$C:$C,A17,'Raw Data'!$K:$K) -> 210755 | F17: =IFERROR(D17/E17,0) -> 0.047301369 | G17: =IFERROR(B17/C17,0) -> 0 | H17: =IFERROR(C17/D17,0) -> 0 | I17: =AVERAGEIF('Raw Data'!$C:$C,A17,'Raw Data'!$Y:$Y) -> 0.4403725

Sheet Scenario Planner
A1: Marketing Budget Scenario Planner
A3: Channel | B3: Current Spend | C3: Current Revenue | D3: Current ROAS | E3: Budget Change % | F3: New Spend | G3: Projected Revenue | H3: Projected ROI
A4: Organic Search | B4: =SUMIF('Raw Data'!$C:$C,A4,'Raw Data'!$R:$R) -> 0 | C4: =SUMIF('Raw Data'!$C:$C,A4,'Raw Data'!$Q:$Q) -> 1220085 | D4: =IFERROR(C4/B4,0) -> 0 | E4: 0 | F4: =B4*(1+E4) -> 0 | G4: =F4*D4 -> 0 | H4: =IFERROR((G4-F4)/F4,0) -> 0
A5: Paid Search | B5: =SUMIF('Raw Data'!$C:$C,A5,'Raw Data'!$R:$R) -> 1063114 | C5: =SUMIF('Raw Data'!$C:$C,A5,'Raw Data'!$Q:$Q) -> 2309514 | D5: =IFERROR(C5/B5,0) -> 2.1724048 | E5: 0.1 | F5: =B5*(1+E5) -> 1169425.4 | G5: =F5*D5 -> 2540465.4 | H5: =IFERROR((G5-F5)/F5,0) -> 1.1724048
A6: Paid Social | B6: =SUMIF('Raw Data'!$C:$C,A6,'Raw Data'!$R:$R) -> 800509 | C6: =SUMIF('Raw Data'!$C:$C,A6,'Raw Data'!$Q:$Q) -> 1466490 | D6: =IFERROR(C6/B6,0) -> 1.8319469 | E6: -0.05 | F6: =B6*(1+E6) -> 760483.55 | G6: =F6*D6 -> 1393165.5 | H6: =IFERROR((G6-F6)/F6,0) -> 0.83194692
A7: Email | B7: =SUMIF('Raw Data'!$C:$C,A7,'Raw Data'!$R:$R) -> 594762 | C7: =SUMIF('Raw Data'!$C:$C,A7,'Raw Data'!$Q:$Q) -> 1268313 | D7: =IFERROR(C7/B7,0) -> 2.1324715 | E7: 0.1 | F7: =B7*(1+E7) -> 654238.2 | G7: =F7*D7 -> 1395144.3 | H7: =IFERROR((G7-F7)/F7,0) -> 1.1324715
A8: Referral | B8: =SUMIF('Raw Data'!$C:$C,A8,'Raw Data'!$R:$R) -> 0 | C8: =SUMIF('Raw Data'!$C:$C,A8,'Raw Data'!$Q:$Q) -> 1341614 | D8: =IFERROR(C8/B8,0) -> 0 | E8: 0 | F8: =B8*(1+E8) -> 0 | G8: =F8*D8 -> 0 | H8: =IFERROR((G8-F8)/F8,0) -> 0
A9: Direct | B9: =SUMIF('Raw Data'!$C:$C,A9,'Raw Data'!$R:$R) -> 0 | C9: =SUMIF('Raw Data'!$C:$C,A9,'Raw Data'!$Q:$Q) -> 1029107 | D9: =IFERROR(C9/B9,0) -> 0 | E9: 0 | F9: =B9*(1+E9) -> 0 | G9: =F9*D9 -> 0 | H9: =IFERROR((G9-F9)/F9,0) -> 0
A12: Notes
A13: Blue input cells in Budget Change % can be adjusted for different spend scenarios.

Sheet SEO_SEM Analysis
A1: SEO and SEM Analysis
A3: Metric | B3: Formula / Source | C3: Interpretation
A4: SEO Revenue | B4: =SUMIF('Raw Data'!C:C,"Organic Search",'Raw Data'!Q:Q) -> 1220085 | C4: Organic revenue value
A5: SEM Revenue | B5: =SUMIF('Raw Data'!C:C,"Paid Search",'Raw Data'!Q:Q) -> 2309514 | C5: Paid search revenue value
A6: SEM Spend | B6: =SUMIF('Raw Data'!C:C,"Paid Search",'Raw Data'!R:R) -> 1063114 | C6: Paid search budget
A7: SEM ROAS | B7: =IFERROR(B5/B6,0) -> 2.1724048 | C7: Paid search return
A8: Avg SEO Position | B8: =AVERAGEIF('Raw Data'!C:C,"Organic Search",'Raw Data'!Z:Z) -> 17.473684 | C8: SEO visibility
A9: Avg Landing Page Score | B9: =AVERAGE('Raw Data'!AA:AA) -> 79.925 | C9: Landing page quality
A12: SEO Recommendation | B12: Improve metadata, internal links, and landing page content for keywords ranking positions 8-20.
A13: SEM Recommendation | B13: Move budget toward campaigns with ROAS above target and CPA below target.

Sheet AB Testing
A1: A/B Test Summary
A3: Variant | B3: Sessions | C3: Orders | D3: Conversion Rate | E3: Revenue | F3: Revenue/User | G3: Lift vs Control
A4: A - Control | B4: =SUMIF('Raw Data'!$H:$H,A4,'Raw Data'!$K:$K) -> 738513 | C4: =SUMIF('Raw Data'!$H:$H,A4,'Raw Data'!$O:$O) -> 41587 | D4: =IFERROR(C4/B4,0) -> 0.056311805 | E4: =SUMIF('Raw Data'!$H:$H,A4,'Raw Data'!$Q:$Q) -> 4242913 | F4: =IFERROR(E4/B4,0) -> 5.745211 | G4: =IFERROR((D4-$D$4)/$D$4,0) -> 0
A5: B - New Experience | B5: =SUMIF('Raw Data'!$H:$H,A5,'Raw Data'!$K:$K) -> 748408 | C5: =SUMIF('Raw Data'!$H:$H,A5,'Raw Data'!$O:$O) -> 38922 | D5: =IFERROR(C5/B5,0) -> 0.052006392 | E5: =SUMIF('Raw Data'!$H:$H,A5,'Raw Data'!$Q:$Q) -> 4392210 | F5: =IFERROR(E5/B5,0) -> 5.8687374 | G5: =IFERROR((D5-$D$4)/$D$4,0) -> -0.076456663
A8: Decision Rule | B8: Roll out Variant B if conversion lift is positive and revenue/user is above control.
A9: Recommendation | B9: =IF(G5>0,"Scale Variant B to more traffic","Keep Control and retest") -> Keep Control and retest

Sheet Raw Data
A1: Date | B1: Month | C1: Channel | D1: Device | E1: Category | F1: Campaign | G1: Keyword_or_Audience | H1: Experiment_Variant | I1: Impressions | J1: Clicks | K1: Sessions | L1: Leads | M1: Cart_Additions | N1: Checkout_Starts | O1: Orders | P1: Purchases | Q1: Revenue | R1: Spend | S1: AOV | T1: CTR | U1: Conversion_Rate | V1: CPA | W1: CPC | X1: ROAS | Y1: Retention_Rate | Z1: SEO_Avg_Position | AA1: Landing_Page_Score | AB1: Customer_Satisfaction
A2: 2026-01-01 | B2: Jan | C2: Paid Search | D2: Desktop | E2: Home | F2: Paid_Search_Campaign_1 | G2: summer outfits | H2: A - Control | I2: 114625 | J2: 6191 | K2: 6310 | L2: 1036 | M2: 2029 | N2: 800 | O2: 341 | P2: 341 | Q2: 54219 | R2: 28032 | S2: 159 | T2: 0.054 | U2: 0.054 | V2: 82.21 | W2: 4.53 | X2: 1.93 | Y2: 0.6241 | AA2: 68 | AB2: 4.7
A3: 2026-01-02 | B3: Jan | C3: Organic Search | D3: Tablet | E3: Fitness | F3: Organic_Search_Campaign_1 | G3: protein powder | H3: B - New Experience | I3: 106672 | J3: 3516 | K3: 2869 | L3: 354 | M3: 427 | N3: 277 | O3: 132 | P3: 132 | Q3: 12936 | R3: 0 | S3: 98 | T3: 0.033 | U3: 0.046 | V3: 0 | W3: 0 | X3: 0 | Y3: 0.3541 | Z3: 10 | AA3: 98 | AB3: 4.3
A4: 2026-01-03 | B4: Jan | C4: Referral | D4: Tablet | E4: Grocery | F4: Referral_Campaign_2 | G4: home office desk | H4: A - Control | I4: 90066 | J4: 6793 | K4: 6578 | L4: 930 | M4: 1119 | N4: 625 | O4: 511 | P4: 511 | Q4: 24017 | R4: 0 | S4: 47 | T4: 0.0754 | U4: 0.0777 | V4: 0 | W4: 0 | X4: 0 | Y4: 0.5857 | AA4: 92 | AB4: 4.6
A5: 2026-01-04 | B5: Jan | C5: Referral | D5: Desktop | E5: Fitness | F5: Referral_Campaign_4 | G5: best wireless earbuds | H5: A - Control | I5: 262023 | J5: 9265 | K5: 7297 | L5: 1596 | M5: 1083 | N5: 713 | O5: 536 | P5: 536 | Q5: 36984 | R5: 0 | S5: 69 | T5: 0.0354 | U5: 0.0735 | V5: 0 | W5: 0 | X5: 0 | Y5: 0.4733 | AA5: 78 | AB5: 4.4
A6: 2026-01-05 | B6: Jan | C6: Organic Search | D6: Mobile | E6: Grocery | F6: Organic_Search_Campaign_5 | G6: summer outfits | H6: B - New Experience | I6: 49446 | J6: 3493 | K6: 3322 | L6: 645 | M6: 721 | N6: 371 | O6: 105 | P6: 105 | Q6: 18060 | R6: 0 | S6: 172 | T6: 0.0706 | U6: 0.0316 | V6: 0 | W6: 0 | X6: 0 | Y6: 0.4825 | Z6: 4 | AA6: 65 | AB6: 4.8
A7: 2026-01-06 | B7: Jan | C7: Paid Social | D7: Desktop | E7: Fitness | F7: Paid_Social_Campaign_3 | G7: best wireless earbuds | H7: B - New Experience | I7: 236815 | J7: 18949 | K7: 18399 | L7: 3284 | M7: 4282 | N7: 2938 | O7: 946 | P7: 946 | Q7: 78518 | R7: 21336 | S7: 83 | T7: 0.08 | U7: 0.0514 | V7: 22.55 | W7: 1.13 | X7: 3.68 | Y7: 0.4245 | AA7: 95 | AB7: 4.4
A8: 2026-01-07 | B8: Jan | C8: Paid Search | D8: Mobile | E8: Apparel | F8: Paid_Search_Campaign_5 | G8: home office desk | H8: A - Control | I8: 39171 | J8: 3103 | K8: 2532 | L8: 233 | M8: 882 | N8: 332 | O8: 78 | P8: 78 | Q8: 12324 | R8: 13505 | S8: 158 | T8: 0.0792 | U8: 0.0308 | V8: 173.14 | W8: 4.35 | X8: 0.91 | Y8: 0.5525 | AA8: 70 | AB8: 4.4
A9: 2026-01-08 | B9: Jan | C9: Organic Search | D9: Tablet | E9: Apparel | F9: Organic_Search_Campaign_4 | G9: home office desk | H9: A - Control | I9: 139305 | J9: 8406 | K9: 7361 | L9: 631 | M9: 1220 | N9: 584 | O9: 444 | P9: 444 | Q9: 62604 | R9: 0 | S9: 141 | T9: 0.0603 | U9: 0.0603 | V9: 0 | W9: 0 | X9: 0 | Y9: 0.5525 | Z9: 18 | AA9: 65 | AB9: 4.7
A10: 2026-01-09 | B10: Jan | C10: Direct | D10: Desktop | E10: Home | F10: Direct_Campaign_5 | G10: summer outfits | H10: A - Control | I10: 83703 | J10: 1395 | K10: 1034 | L10: 101 | M10: 330 | N10: 212 | O10: 48 | P10: 48 | Q10: 2496 | R10: 0 | S10: 52 | T10: 0.0167 | U10: 0.0464 | V10: 0 | W10: 0 | X10: 0 | Y10: 0.6341 | AA10: 93 | AB10: 4
A11: 2026-01-10 | B11: Jan | C11: Paid Social | D11: Desktop | E11: Electronics | F11: Paid_Social_Campaign_3 | G11: best wireless earbuds | H11: A - Control | I11: 251281 | J11: 15827 | K11: 15907 | L11: 1827 | M11: 5197 | N11: 2562 | O11: 1048 | P11: 1048 | Q11: 101656 | R11: 32366 | S11: 97 | T11: 0.063 | U11: 0.0659 | V11: 30.88 | W11: 2.04 | X11: 3.14 | Y11: 0.3708 | AA11: 78 | AB11: 4.2
A12: 2026-01-11 | B12: Jan | C12: Paid Social | D12: Desktop | E12: Beauty | F12: Paid_Social_Campaign_5 | G12: mens running shoes | H12: B - New Experience | I12: 55077 | J12: 748 | K12: 604 | L12: 81 | M12: 134 | N12: 64 | O12: 18 | P12: 18 | Q12: 2664 | R12: 35377 | S12: 148 | T12: 0.0136 | U12: 0.0298 | V12: 1965.39 | W12: 47.3 | X12: 0.08 | Y12: 0.3863 | AA12: 90 | AB12: 4.6
A13: 2026-01-12 | B13: Jan | C13: Direct | D13: Desktop | E13: Home | F13: Direct_Campaign_2 | G13: skincare bundle | H13: B - New Experience | I13: 217604 | J13: 3341 | K13: 3155 | L13: 380 | M13: 892 | N13: 442 | O13: 159 | P13: 159 | Q13: 18126 | R13: 0 | S13: 114 | T13: 0.0154 | U13: 0.0504 | V13: 0 | W13: 0 | X13: 0 | Y13: 0.2668 | AA13: 66 | AB13: 4.7
A14: 2026-01-13 | B14: Jan | C14: Referral | D14: Desktop | E14: Apparel | F14: Referral_Campaign_5 | G14: protein powder | H14: A - Control | I14: 52488 | J14: 1332 | K14: 1173 | L14: 113 | M14: 357 | N14: 190 | O14: 93 | P14: 93 | Q14: 10881 | R14: 0 | S14: 117 | T14: 0.0254 | U14: 0.0793 | V14: 0 | W14: 0 | X14: 0 | Y14: 0.4216 | AA14: 82 | AB14: 4.8
A15: 2026-01-14 | B15: Jan | C15: Direct | D15: Desktop | E15: Home | F15: Direct_Campaign_2 | G15: mens running shoes | H15: B - New Experience | I15: 183037 | J15: 6980 | K15: 5548 | L15: 451 | M15: 1639 | N15: 990 | O15: 184 | P15: 184 | Q15: 29992 | R15: 0 | S15: 163 | T15: 0.0381 | U15: 0.0332 | V15: 0 | W15: 0 | X15: 0 | Y15: 0.2992 | AA15: 98 | AB15: 4
A16: 2026-01-15 | B16: Jan | C16: Referral | D16: Tablet | E16: Apparel | F16: Referral_Campaign_4 | G16: best wireless earbuds | H16: A - Control | I16: 220296 | J16: 12790 | K16: 12285 | L16: 2252 | M16: 3387 | N16: 1297 | O16: 1046 | P16: 1046 | Q16: 74266 | R16: 0 | S16: 71 | T16: 0.0581 | U16: 0.0851 | V16: 0 | W16: 0 | X16: 0 | Y16: 0.4045 | AA16: 88 | AB16: 4.4
A17: 2026-01-16 | B17: Jan | C17: Organic Search | D17: Desktop | E17: Home | F17: Organic_Search_Campaign_5 | G17: home office desk | H17: A - Control | I17: 64094 | J17: 1309 | K17: 1240 | L17: 151 | M17: 255 | N17: 117 | O17: 71 | P17: 71 | Q17: 6461 | R17: 0 | S17: 91 | T17: 0.0204 | U17: 0.0573 | V17: 0 | W17: 0 | X17: 0 | Y17: 0.5112 | Z17: 10 | AA17: 73 | AB17: 3.8
A18: 2026-01-17 | B18: Jan | C18: Paid Search | D18: Mobile | E18: Fitness | F18: Paid_Search_Campaign_1 | G18: summer outfits | H18: B - New Experience | I18: 21334 | J18: 917 | K18: 823 | L18: 169 | M18: 287 | N18: 166 | O18: 30 | P18: 30 | Q18: 2730 | R18: 13926 | S18: 91 | T18: 0.043 | U18: 0.0365 | V18: 464.2 | W18: 15.19 | X18: 0.2 | Y18: 0.6374 | AA18: 96 | AB18: 4.1
A19: 2026-01-18 | B19: Jan | C19: Direct | D19: Mobile | E19: Grocery | F19: Direct_Campaign_2 | G19: summer outfits | H19: A - Control | I19: 179075 | J19: 9145 | K19: 7161 | L19: 666 | M19: 2199 | N19: 1386 | O19: 341 | P19: 341 | Q19: 44330 | R19: 0 | S19: 130 | T19: 0.0511 | U19: 0.0476 | V19: 0 | W19: 0 | X19: 0 | Y19: 0.6756 | AA19: 84 | AB19: 4.5
A20: 2026-01-19 | B20: Jan | C20: Paid Social | D20: Mobile | E20: Fitness | F20: Paid_Social_Campaign_2 | G20: best wireless earbuds | H20: A - Control | I20: 153378 | J20: 12717 | K20: 9580 | L20: 1739 | M20: 1975 | N20: 1079 | O20: 400 | P20: 400 | Q20: 22000 | R20: 29917 | S20: 55 | T20: 0.0829 | U20: 0.0418 | V20: 74.79 | W20: 2.35 | X20: 0.74 | Y20: 0.5299 | AA20: 74 | AB20: 4
A21: 2026-01-20 | B21: Jan | C21: Email | D21: Tablet | E21: Fitness | F21: Email_Campaign_5 | G21: summer outfits | H21: B - New Experience | I21: 190323 | J21: 14087 | K21: 14538 | L21: 1268 | M21: 3592 | N21: 2214 | O21: 1048 | P21: 1048 | Q21: 124712 | R21: 18394 | S21: 119 | T21: 0.074 | U21: 0.0721 | V21: 17.55 | W21: 1.31 | X21: 6.78 | Y21: 0.4976 | AA21: 83 | AB21: 3.8
A22: 2026-01-21 | B22: Jan | C22: Email | D22: Desktop | E22: Apparel | F22: Email_Campaign_4 | G22: skincare bundle | H22: B - New Experience | I22: 129188 | J22: 9038 | K22: 8346 | L22: 848 | M22: 1041 | N22: 636 | O22: 596 | P22: 596 | Q22: 95956 | R22: 2752 | S22: 161 | T22: 0.07 | U22: 0.0714 | V22: 4.62 | W22: 0.3 | X22: 34.87 | Y22: 0.5159 | AA22: 68 | AB22: 3.6
A23: 2026-01-22 | B23: Jan | C23: Direct | D23: Tablet | E23: Electronics | F23: Direct_Campaign_1 | G23: summer outfits | H23: B - New Experience | I23: 67736 | J23: 2606 | K23: 2105 | L23: 227 | M23: 320 | N23: 206 | O23: 81 | P23: 81 | Q23: 10206 | R23: 0 | S23: 126 | T23: 0.0385 | U23: 0.0385 | V23: 0 | W23: 0 | X23: 0 | Y23: 0.4772 | AA23: 80 | AB23: 4.5
A24: 2026-01-23 | B24: Jan | C24: Direct | D24: Mobile | E24: Home | F24: Direct_Campaign_4 | G24: mens running shoes | H24: B - New Experience | I24: 74554 | J24: 2097 | K24: 1762 | L24: 329 | M24: 365 | N24: 247 | O24: 119 | P24: 119 | Q24: 13447 | R24: 0 | S24: 113 | T24: 0.0281 | U24: 0.0675 | V24: 0 | W24: 0 | X24: 0 | Y24: 0.6012 | AA24: 66 | AB24: 4.8
A25: 2026-01-24 | B25: Jan | C25: Referral | D25: Desktop | E25: Fitness | F25: Referral_Campaign_2 | G25: skincare bundle | H25: B - New Experience | I25: 80245 | J25: 6262 | K25: 4878 | L25: 487 | M25: 1280 | N25: 458 | O25: 520 | P25: 458 | Q25: 43680 | R25: 0 | S25: 84 | T25: 0.078 | U25: 0.1066 | V25: 0 | W25: 0 | X25: 0 | Y25: 0.5847 | AA25: 95 | AB25: 4.1
A26: 2026-01-25 | B26: Jan | C26: Direct | D26: Desktop | E26: Electronics | F26: Direct_Campaign_1 | G26: home office desk | H26: B - New Experience | I26: 197455 | J26: 2782 | K26: 2759 | L26: 471 | M26: 441 | N26: 184 | O26: 136 | P26: 136 | Q26: 7208 | R26: 0 | S26: 53 | T26: 0.0141 | U26: 0.0493 | V26: 0 | W26: 0 | X26: 0 | Y26: 0.3743 | AA26: 98 | AB26: 4
A27: 2026-01-26 | B27: Jan | C27: Email | D27: Desktop | E27: Electronics | F27: Email_Campaign_2 | G27: home office desk | H27: A - Control | I27: 261144 | J27: 9559 | K27: 8316 | L27: 1598 | M27: 2032 | N27: 979 | O27: 602 | P27: 602 | Q27: 45752 | R27: 28188 | S27: 76 | T27: 0.0366 | U27: 0.0724 | V27: 46.82 | W27: 2.95 | X27: 1.62 | Y27: 0.358 | AA27: 88 | AB27: 4.2
A28: 2026-01-27 | B28: Jan | C28: Organic Search | D28: Desktop | E28: Home | F28: Organic_Search_Campaign_2 | G28: protein powder | H28: A - Control | I28: 38033 | J28: 582 | K28: 616 | L28: 70 | M28: 136 | N28: 66 | O28: 17 | P28: 17 | Q28: 1921 | R28: 0 | S28: 113 | T28: 0.0153 | U28: 0.0276 | V28: 0 | W28: 0 | X28: 0 | Y28: 0.6377 | Z28: 28 | AA28: 66 | AB28: 3.7
A29: 2026-01-28 | B29: Jan | C29: Paid Search | D29: Desktop | E29: Home | F29: Paid_Search_Campaign_5 | G29: mens running shoes | H29: A - Control | I29: 260732 | J29: 10645 | K29: 9006 | L29: 1548 | M29: 1560 | N29: 1002 | O29: 416 | P29: 416 | Q29: 52416 | R29: 33549 | S29: 126 | T29: 0.0408 | U29: 0.0462 | V29: 80.65 | W29: 3.15 | X29: 1.56 | Y29: 0.3037 | AA29: 83 | AB29: 4.2
A30: 2026-01-29 | B30: Jan | C30: Paid Search | D30: Mobile | E30: Fitness | F30: Paid_Search_Campaign_3 | G30: home office desk | H30: A - Control | I30: 97437 | J30: 5089 | K30: 5491 | L30: 638 | M30: 1774 | N30: 707 | O30: 387 | P30: 387 | Q30: 41022 | R30: 29699 | S30: 106 | T30: 0.0522 | U30: 0.0705 | V30: 76.74 | W30: 5.84 | X30: 1.38 | Y30: 0.366 | AA30: 91 | AB30: 4.1
A31: 2026-01-30 | B31: Jan | C31: Email | D31: Desktop | E31: Home | F31: Email_Campaign_1 | G31: home office desk | H31: A - Control | I31: 94574 | J31: 7752 | K31: 8017 | L31: 1745 | M31: 1873 | N31: 1202 | O31: 696 | P31: 696 | Q31: 40368 | R31: 11687 | S31: 58 | T31: 0.082 | U31: 0.0868 | V31: 16.79 | W31: 1.51 | X31: 3.45 | Y31: 0.2427 | AA31: 84 | AB31: 4
A32: 2026-01-31 | B32: Jan | C32: Organic Search | D32: Desktop | E32: Grocery | F32: Organic_Search_Campaign_2 | G32: summer outfits | H32: B - New Experience | I32: 79265 | J32: 3737 | K32: 3691 | L32: 790 | M32: 1194 | N32: 725 | O32: 177 | P32: 177 | Q32: 14514 | R32: 0 | S32: 82 | T32: 0.0471 | U32: 0.048 | V32: 0 | W32: 0 | X32: 0 | Y32: 0.5523 | Z32: 17 | AA32: 82 | AB32: 4.5
A33: 2026-02-01 | B33: Feb | C33: Paid Search | D33: Mobile | E33: Grocery | F33: Paid_Search_Campaign_3 | G33: home office desk | H33: A - Control | I33: 159249 | J33: 9887 | K33: 9771 | L33: 843 | M33: 1325 | N33: 831 | O33: 505 | P33: 505 | Q33: 90900 | R33: 24835 | S33: 180 | T33: 0.0621 | U33: 0.0517 | V33: 49.18 | W33: 2.51 | X33: 3.66 | Y33: 0.4023 | AA33: 82 | AB33: 4.6
A34: 2026-02-02 | B34: Feb | C34: Paid Social | D34: Mobile | E34: Electronics | F34: Paid_Social_Campaign_2 | G34: mens running shoes | H34: A - Control | I34: 150497 | J34: 3113 | K34: 2686 | L34: 311 | M34: 616 | N34: 402 | O34: 71 | P34: 71 | Q34: 12354 | R34: 10159 | S34: 174 | T34: 0.0207 | U34: 0.0264 | V34: 143.08 | W34: 3.26 | X34: 1.22 | Y34: 0.4418 | AA34: 87 | AB34: 3.8
A35: 2026-02-03 | B35: Feb | C35: Paid Search | D35: Tablet | E35: Grocery | F35: Paid_Search_Campaign_5 | G35: protein powder | H35: A - Control | I35: 77341 | J35: 2089 | K35: 1898 | L35: 334 | M35: 533 | N35: 375 | O35: 81 | P35: 81 | Q35: 12717 | R35: 19668 | S35: 157 | T35: 0.027 | U35: 0.0427 | V35: 242.81 | W35: 9.42 | X35: 0.65 | Y35: 0.3842 | AA35: 96 | AB35: 3.8
A36: 2026-02-04 | B36: Feb | C36: Paid Social | D36: Mobile | E36: Beauty | F36: Paid_Social_Campaign_5 | G36: best wireless earbuds | H36: B - New Experience | I36: 194409 | J36: 15708 | K36: 11810 | L36: 1562 | M36: 1649 | N36: 837 | O36: 632 | P36: 632 | Q36: 113128 | R36: 15565 | S36: 179 | T36: 0.0808 | U36: 0.0535 | V36: 24.63 | W36: 0.99 | X36: 7.27 | Y36: 0.2168 | AA36: 96 | AB36: 4.7
A37: 2026-02-05 | B37: Feb | C37: Paid Search | D37: Tablet | E37: Grocery | F37: Paid_Search_Campaign_1 | G37: home office desk | H37: B - New Experience | I37: 182652 | J37: 3236 | K37: 2571 | L37: 491 | M37: 543 | N37: 334 | O37: 132 | P37: 132 | Q37: 19404 | R37: 7120 | S37: 147 | T37: 0.0177 | U37: 0.0513 | V37: 53.94 | W37: 2.2 | X37: 2.73 | Y37: 0.4654 | AA37: 80 | AB37: 4
A38: 2026-02-06 | B38: Feb | C38: Paid Social | D38: Desktop | E38: Electronics | F38: Paid_Social_Campaign_3 | G38: summer outfits | H38: B - New Experience | I38: 118338 | J38: 6356 | K38: 6354 | L38: 727 | M38: 1864 | N38: 1175 | O38: 201 | P38: 201 | Q38: 15678 | R38: 18766 | S38: 78 | T38: 0.0537 | U38: 0.0316 | V38: 93.36 | W38: 2.95 | X38: 0.84 | Y38: 0.3027 | AA38: 77 | AB38: 4.3
A39: 2026-02-07 | B39: Feb | C39: Email | D39: Tablet | E39: Fitness | F39: Email_Campaign_1 | G39: best wireless earbuds | H39: A - Control | I39: 65136 | J39: 2041 | K39: 1672 | L39: 212 | M39: 232 | N39: 166 | O39: 105 | P39: 105 | Q39: 8715 | R39: 14002 | S39: 83 | T39: 0.0313 | U39: 0.0628 | V39: 133.35 | W39: 6.86 | X39: 0.62 | Y39: 0.2887 | AA39: 70 | AB39: 4.6
A40: 2026-02-08 | B40: Feb | C40: Paid Search | D40: Desktop | E40: Fitness | F40: Paid_Search_Campaign_5 | G40: mens running shoes | H40: B - New Experience | I40: 99476 | J40: 5256 | K40: 4785 | L40: 1045 | M40: 1270 | N40: 610 | O40: 373 | P40: 373 | Q40: 52593 | R40: 12139 | S40: 141 | T40: 0.0528 | U40: 0.078 | V40: 32.54 | W40: 2.31 | X40: 4.33 | Y40: 0.1869 | AA40: 78 | AB40: 3.9
...

Sheet Data Dictionary
A1: Data Dictionary
A3: Field | B3: Definition
A4: Revenue | B4: Total simulated sales revenue generated.
A5: Spend | B5: Marketing campaign spend.
A6: ROAS | B6: Revenue divided by marketing spend.
A7: CPA | B7: Spend divided by orders.
A8: Conversion Rate | B8: Orders divided by sessions.
A9: CTR | B9: Clicks divided by impressions.
A10: SEO Average Position | B10: Average search ranking position for organic keywords.
A11: Landing Page Score | B11: Quality score for SEO/SEM landing page experience.
